<mujoco><option gravity="0 0 -10" /><default><geom rgba=".8 .6 .4 1" /></default><asset><texture type="skybox" builtin="gradient" rgb1="1 1 1" rgb2=".6 .8 1" width="400" height="400" /></asset><worldbody><light pos="0 1 1" dir="0 -1 -1" diffuse="1 1 1" /><body name="body0" pos="0 0 0"><joint name="joint0" type="hinge" axis="0 0 1" /><geom name="geom0" type="capsule" size="0.04" fromto=" " /></body><body name="body1" pos=" "><joint name="joint1" type="slide" axis="1 0 0"><parent body="joint0" /><parentframe><pose axisangle=" " /></parentframe></joint><geom name="geom1" type="capsule" size="0.04" fromto=" " /></body></worldbody></mujoco>